Workbook

Sheet BOM
A1: Bill of Materials
A2: All costs in INR (₹). Blue = entered values; black = formulas. Costs as provided by the user.
A4: # | B4: Category | C4: Component | D4: Cost (₹)
A5: 1 | B5: Mechanical | C5: Outer Body | D5: 9000
A6: 2 | B6: Mechanical | C6: Frame | D6: 3500
A7: 3 | B7: Mechanical | C7: Compartments (4) | D7: 1800
A8: 4 | B8: Mechanical | C8: Gate, drop door, sorter | D8: 5000
A9: 5 | B9: Mechanical | C9: Chamber interior and window | D9: 3000
A10: 6 | B10: Mechanical | C10: Sorter bearing | D10: 1200
A11: 7 | B11: Mechanical | C11: Seals and fasteners | D11: 1500
C12: Mechanical subtotal | D12: =SUM(D5:D11) -> 25000
A14: 8 | B14: Power & Safety | C14: Main power supply | D14: 1499
A15: 9 | B15: Power & Safety | C15: Pi power supply | D15: 1235
A16: 10 | B16: Power & Safety | C16: DC-DC converter, servo rail | D16: 900
A17: 11 | B17: Power & Safety | C17: DC-DC converter, logic | D17: 250
A18: 12 | B18: Power & Safety | C18: Protection | D18: 1800
A19: 13 | B19: Power & Safety | C19: Emergency stop and safety relay | D19: 6500
A20: 14 | B20: Power & Safety | C20: Service-door interlock | D20: 1200
A21: 15 | B21: Power & Safety | C21: Indicators | D21: 700
A22: 16 | B22: Power & Safety | C22: Electrical enclosure and wiring set | D22: 5000
C23: Power & Safety subtotal | D23: =SUM(D14:D22) -> 19084
A25: 17 | B25: Sensing | C25: Inlet item sensor | D25: 3500
A26: 18 | B26: Sensing | C26: Metal sensor | D26: 767
A27: 19 | B27: Sensing | C27: Homing sensor (sorter) | D27: 450
A28: 20 | B28: Sensing | C28: Load cell, inspection chamber | D28: 100
A29: 21 | B29: Sensing | C29: Load cell amplifier | D29: 119
C30: Sensing subtotal | D30: =SUM(D25:D29) -> 4936
A32: 22 | B32: Compute & Control | C32: Raspberry Pi 5 | D32: 12000
A33: 23 | B33: Compute & Control | C33: Pi 5 camera cable | D33: 395
A34: 24 | B34: Compute & Control | C34: Pi 5 active cooler | D34: 488
A35: 25 | B35: Compute & Control | C35: ESP32-S3-DevKitC-1 | D35: 1003
A36: 26 | B36: Compute & Control | C36: Storage | D36: 700
A37: 27 | B37: Compute & Control | C37: Interface PCB | D37: 2500
A38: 28 | B38: Compute & Control | C38: 24 V input module | D38: 550
A39: 29 | B39: Compute & Control | C39: Output module | D39: 450
C40: Compute & Control subtotal | D40: =SUM(D32:D39) -> 18086
A42: 30 | B42: Motion | C42: Sorting stepper motor | D42: 1699
A43: 31 | B43: Motion | C43: Stepper driver | D43: 2699
A44: 32 | B44: Motion | C44: Gate and drop-door servos | D44: 4200
C45: Motion subtotal | D45: =SUM(D42:D44) -> 8598
...

Sheet Summary
A1: Cost Summary by Category
A3: Category | B3: Items | C3: Subtotal (₹) | D3: Share of total
A4: Mechanical | B4: =COUNTIF(BOM!$B$5:$B$51,A4) -> 7 | C4: =BOM!D12 -> 25000 | D4: =C4/$C$10 -> 0.28538161
A5: Power & Safety | B5: =COUNTIF(BOM!$B$5:$B$51,A5) -> 9 | C5: =BOM!D23 -> 19084 | D5: =C5/$C$10 -> 0.21784891
A6: Sensing | B6: =COUNTIF(BOM!$B$5:$B$51,A6) -> 5 | C6: =BOM!D30 -> 4936 | D6: =C6/$C$10 -> 0.056345746
A7: Compute & Control | B7: =COUNTIF(BOM!$B$5:$B$51,A7) -> 8 | C7: =BOM!D40 -> 18086 | D7: =C7/$C$10 -> 0.20645647
A8: Motion | B8: =COUNTIF(BOM!$B$5:$B$51,A8) -> 3 | C8: =BOM!D45 -> 8598 | D8: =C8/$C$10 -> 0.098148444
A9: Vision | B9: =COUNTIF(BOM!$B$5:$B$51,A9) -> 3 | C9: =BOM!D50 -> 11898 | D9: =C9/$C$10 -> 0.13581882
A10: Total | B10: =SUM(B4:B9) -> 35 | C10: =SUM(C4:C9) -> 87602 | D10: =SUM(D4:D9) -> 1
A12: Check: Summary total equals BOM grand total | C12: =IF(C10=BOM!D52,"OK","MISMATCH") -> OK
